Traceback (most recent call last):
  File "/usr/local/lib/python3.9/site-packages/jupyter_cache/executors/utils.py", line 51, in single_nb_execution
    executenb(
  File "/Users/servajean/Library/Python/3.9/lib/python/site-packages/nbclient/client.py", line 1087, in execute
    return NotebookClient(nb=nb, resources=resources, km=km, **kwargs).execute()
  File "/Users/servajean/Library/Python/3.9/lib/python/site-packages/nbclient/util.py", line 74, in wrapped
    return just_run(coro(*args, **kwargs))
  File "/Users/servajean/Library/Python/3.9/lib/python/site-packages/nbclient/util.py", line 53, in just_run
    return loop.run_until_complete(coro)
  File "/usr/local/Cellar/python@3.9/3.9.4/Frameworks/Python.framework/Versions/3.9/lib/python3.9/asyncio/base_events.py", line 642, in run_until_complete
    return future.result()
  File "/Users/servajean/Library/Python/3.9/lib/python/site-packages/nbclient/client.py", line 540, in async_execute
    await self.async_execute_cell(
  File "/Users/servajean/Library/Python/3.9/lib/python/site-packages/nbclient/client.py", line 832, in async_execute_cell
    self._check_raise_for_error(cell, exec_reply)
  File "/Users/servajean/Library/Python/3.9/lib/python/site-packages/nbclient/client.py", line 740, in _check_raise_for_error
    raise CellExecutionError.from_cell_and_msg(cell, exec_reply['content'])
nbclient.exceptions.CellExecutionError: An error occurred while executing the following cell:
------------------
class SyntheticDataset(TorchDataset):
    def __init__(self, X, y):
        self.dataset, self.label = X, y

    def __len__(self):
        return len(self.label)

    def __getitem__(self, idx):
        return torch.from_numpy(self.dataset[idx]).float(), int(self.label[idx])
    
dataset = SyntheticDataset(X, y)
------------------

[0;31m---------------------------------------------------------------------------[0m
[0;31mNameError[0m                                 Traceback (most recent call last)
[0;32m<ipython-input-43-3612a06defa2>[0m in [0;36m<module>[0;34m[0m
[0;32m----> 1[0;31m [0;32mclass[0m [0mSyntheticDataset[0m[0;34m([0m[0mTorchDataset[0m[0;34m)[0m[0;34m:[0m[0;34m[0m[0;34m[0m[0m
[0m[1;32m      2[0m     [0;32mdef[0m [0m__init__[0m[0;34m([0m[0mself[0m[0;34m,[0m [0mX[0m[0;34m,[0m [0my[0m[0;34m)[0m[0;34m:[0m[0;34m[0m[0;34m[0m[0m
[1;32m      3[0m         [0mself[0m[0;34m.[0m[0mdataset[0m[0;34m,[0m [0mself[0m[0;34m.[0m[0mlabel[0m [0;34m=[0m [0mX[0m[0;34m,[0m [0my[0m[0;34m[0m[0;34m[0m[0m
[1;32m      4[0m [0;34m[0m[0m
[1;32m      5[0m     [0;32mdef[0m [0m__len__[0m[0;34m([0m[0mself[0m[0;34m)[0m[0;34m:[0m[0;34m[0m[0;34m[0m[0m

[0;31mNameError[0m: name 'TorchDataset' is not defined
NameError: name 'TorchDataset' is not defined

